<?xml version="1.0" encoding="utf-8"?>
<robot
  name="swcr">
  <link name="base_link">
    <visual>
      <origin
        xyz="0 0 0"
        rpy="0 0 0" />
      <geometry>
        <mesh
          filename="package://swcr/meshes/base_link.dae" />
      </geometry>
      <material
        name="">
        <color
          rgba="0.101960784313725 0.101960784313725 0.101960784313725 1" />
      </material>
    </visual>
    <collision>
      <origin
        xyz="0 0 0"
        rpy="0 0 0" />
      <geometry>
        <mesh
          filename="package://swcr/meshes/base_link.dae" />
      </geometry>
    </collision>
  </link>
  <link name="Bin_Link">
    <visual>
      <origin
      xyz="0.045 -0.00500000000000001 0.0525"
      rpy="3.14159265358979 0 -1.5707963267949" />
      <geometry>
        <mesh
          filename="package://swcr/meshes/Bin_Link.dae" />
      </geometry>
      <material
        name="">
        <color
          rgba="0.898039215686275 0.917647058823529 0.929411764705882 1" />
      </material>
    </visual>
    <collision>
      <origin
      xyz="0.045 -0.00500000000000001 0.0525"
      rpy="3.14159265358979 0 -1.5707963267949" />
      <geometry>
        <mesh
          filename="package://swcr/meshes/Bin_Link.dae" />
      </geometry>
    </collision>
  </link>
  <joint
    name="Bin_joint"
    type="fixed">
    <origin
      xyz="0.045 -0.00500000000000001 0.0525"
      rpy="3.14159265358979 0 -1.5707963267949" />
    <parent
      link="base_link" />
    <child
      link="Bin_Link" />
    <axis
      xyz="0 0 0" />
  </joint>
  <link name="Pan_Link">
    <visual>
      <origin
      xyz="0.11821106537886 0 0.0043695506838019"
      rpy="1.5707963267949 -0.0688308576600601 0" />
      <geometry>
        <mesh
          filename="package://swcr/meshes/Pan_Link.dae" />
      </geometry>
      <material
        name="">
        <color
          rgba="0.792156862745098 0.819607843137255 0.933333333333333 1" />
      </material>
    </visual>
    <collision>
      <origin
      xyz="0.11821106537886 0 0.0043695506838019"
      rpy="1.5707963267949 -0.0688308576600601 0" />
      <geometry>
        <mesh
          filename="package://swcr/meshes/Pan_Link.dae" />
      </geometry>
    </collision>
  </link>
  <joint
    name="Pan_joint"
    type="revolute">
    <axis xyz="1 0 0" />
    <limit effort="1000.0" lower="0.0" upper="0.548" velocity="0.5"/>
    <origin
      rpy="1.5707963267949 -0.0688308576600601 0" xyz="0.11821106537886 0 0.0043695506838019"/>
    <parent link="base_link" />
    <child link="Pan_Link" />
  </joint>
  <link
    name="Wheel1L_Link">
    <visual>
      <origin
      xyz="0.085 -0.1513 -0.0175650643543415" />
      <geometry>
        <mesh
          filename="package://swcr/meshes/Wheel1L_Link.dae" />
      </geometry>
      <material
        name="">
        <color
          rgba="0.588235294117647 0.588235294117647 0.631372549019608 1" />
      </material>
    </visual>
    <collision>
     <origin
      xyz="0.085 -0.1513 -0.0175650643543415" />
      <geometry>
        <mesh
          filename="package://swcr/meshes/Wheel1L_Link.dae" />
      </geometry>
    </collision>
  </link>
  <joint
    name="Wheel1L_joint"
    type="continuous">
    <parent
      link="base_link" />
    <child
      link="Wheel1L_Link" />
    <axis
      xyz="0 1 0" />
    <origin
      xyz="0.085 -0.1513 -0.0175650643543415" />    
  </joint>
  <link
    name="Wheel2L_Link">
    <visual>
      <origin
        xyz="0 0 0"
        rpy="0 0 0" />
      <geometry>
        <mesh
          filename="package://swcr/meshes/Wheel2L_Link.dae" />
      </geometry>
      <material
        name="">
        <color
          rgba="0.588235294117647 0.588235294117647 0.631372549019608 1" />
      </material>
    </visual>
    <collision>
      <origin
        xyz="0 0 0"
        rpy="0 0 0" />
      <geometry>
        <mesh
          filename="package://swcr/meshes/Wheel2L_Link.dae" />
      </geometry>
    </collision>
  </link>
  <joint
    name="Wheel2L_joint"
    type="fixed">
    <origin
      xyz="-0.085 -0.1513 -0.0175650643543415"
      rpy="1.86455912828869 0 1.5707963267949" />
    <parent
      link="base_link" />
    <child
      link="Wheel2L_Link" />
    <axis
      xyz="0 0 0" />
  </joint>
  <link
    name="Wheel1R_Link">
    <visual>
      <origin
        xyz="0 0 0"
        rpy="0 0 0" />
      <geometry>
        <mesh
          filename="package://swcr/meshes/Wheel1R_Link.dae" />
      </geometry>
      <material
        name="">
        <color
          rgba="0.588235294117647 0.588235294117647 0.631372549019608 1" />
      </material>
    </visual>
    <collision>
      <origin
        xyz="0 0 0"
        rpy="0 0 0" />
      <geometry>
        <mesh
          filename="package://swcr/meshes/Wheel1R_Link.dae" />
      </geometry>
    </collision>
  </link>
  <joint
    name="Wheel1R_joint"
    type="fixed">
    <origin
      xyz="0.0823186569435573 0.1513 -0.0180989682049121"
      rpy="-1.5707963267949 0 -1.5707963267949" />
    <parent
      link="base_link" />
    <child
      link="Wheel1R_Link" />
    <axis
      xyz="0 0 0" />
  </joint>
  <link
    name="Wheel2R_Link">
    <visual>
      <origin
        xyz="0 0 0"
        rpy="0 0 0" />
      <geometry>
        <mesh
          filename="package://swcr/meshes/Wheel2R_Link.dae" />
      </geometry>
      <material
        name="">
        <color
          rgba="0.588235294117647 0.588235294117647 0.631372549019608 1" />
      </material>
    </visual>
    <collision>
      <origin
        xyz="0 0 0"
        rpy="0 0 0" />
      <geometry>
        <mesh
          filename="package://swcr/meshes/Wheel2R_Link.dae" />
      </geometry>
    </collision>
  </link>
  <joint
    name="Wheel2R_joint"
    type="fixed">
    <origin
      xyz="-0.087681 0.1513 -0.018099"
      rpy="2.7665 0 -1.5708" />
    <parent
      link="base_link" />
    <child
      link="Wheel2R_Link" />
    <axis
      xyz="0 0 0" />
  </joint>
</robot>